Workbook
Name aaa: #REF!
Name ACTIONLOG: {1,2,3,4,5,6,7;"M","T","W","T","F","S","S"}
Name Assumptions: #REF!
Name BLPG_ex_works_4020_€_Non_Oil_mtrls_plus: #REF!
Name BLPG_ex_works_4020_€_Pricelist_plus: #REF!
Name Bob: #REF!
Name ColorStatusIndicators: #REF!
Name Countries: #REF!
Name CurrentQuarter: #REF!
Name cvp: #REF!
Name Day_lookup: {1,2,3,4,5,6,7;"M","T","W","T","F","S","S"}
Name DiscountRate: #REF!
Name ex: #REF!
Name FX: #REF!
Name G: #REF!
Name grades: #REF!
Name GRCs: #REF!
Name Manuf_Antwerp: #REF!
Name Manuf_Hyde: #REF!
Name Manuf_Stanlow: #REF!
Name NumberStatus: #REF!
Name NumberStatusIndicators: #REF!
Name P: #REF!
Name pivot: #REF!
Name Plan16nocapex: #REF!
Name PRINTS: #REF!
Name RM: #REF!
Name SC_Summary: #REF!
Name SChain_BE: #REF!
Name SChain_DK: #REF!
Name SChain_IR: #REF!
Name SChain_NOR: #REF!
Name SChain_SWE: #REF!
Name SChain_UK: #REF!
Name SEVERITY: #REF!
Name stage: #REF!
Name Start_Date: #REF!
Name StatusIndicators: #REF!
Name StatusNumber: #REF!
Name Tax_GRE: #REF!
Name Tax_RoE: #REF!
Name TemporaryPermanent: #REF!
Name ThreeStatusNumber: #REF!
Name Todays_Date: #REF!
Name WHNoMonths: #REF!

Sheet DS Reconciliation
A1: DS RECONCILIATION · Payroll vs Scorecard | H1: Period: | J1: AP09 | K1: Year: | L1: 2026 | M1: SC date: | N1: ="01/"&RIGHT($J$1,2)&"/"&$L$1 -> 01/09/2026
A2: Process | B2: ="Payroll FTE "&$J$1 -> Payroll FTE AP09 | C2: Vacancy | D2: Sick leave | E2: Adjustment | F2: FTE Real | G2: FTE Scorecard | I2: AP Clerk | J2: TL | K2: Mng. | L2: H. Desk | M2: Bank. | N2: Difference | O2: Status | P2: Comments | T2: BSC
A3: P2P | B3: =SUM(B4:B8) -> 14.3125 | C3: =+SUM(C4:C8) -> 2 | D3: =+SUM(D4:D8) -> 3 | E3: =+SUM(E4:E8) -> 1.8 | F3: =+B3+C3-D3-E3 -> 11.5125 | G3: =SUM(G9:G17) -> 50.07 | H3: Breakdown >> | I3: =+SUM(I9:I17) -> 31.14 | J3: =+SUM(J9:J17) -> 7 | K3: =+SUM(K9:K17) -> 2 | L3: =+SUM(L9:L17) -> 6.5 | M3: =+SUM(M9:M17) -> 4.0049312 | N3: =G3-F3 -> 38.5575 | O3: =IF(N(G3)=0,"",IF(ABS(N3)<=0.02,"OK","Review")) -> Review | S3: Banking - Collections | T3: 3
A4: AP Continuos improvement | B4: =SUMIFS(Payroll!$I:$I,Payroll!$D:$D,$J$1,Payroll!$H:$H,"DSS",Payroll!$F:$F,"P2P*",Payroll!$K:$K,$A4) -> 1 | D4: 0 | F4: =+B4+C4-D4-E4 -> 1 | G4: 1 | N4: =G4-F4 -> 0 | O4: =IF(N(G4)=0,"",IF(ABS(N4)<=0.02,"OK","Review")) -> OK | S4: Banking - Payment | T4: 5
A5: AP Help Desk | B5: =SUMIFS(Payroll!$I:$I,Payroll!$D:$D,$J$1,Payroll!$H:$H,"DSS",Payroll!$F:$F,"P2P*",Payroll!$K:$K,$A5) -> 1 | D5: 1 | E5: 0.5 | F5: =+B5+C5-D5-E5 -> -0.5 | G5: =SUM(L9:L17) -> 6.5 | N5: =G5-F5 -> 7 | O5: =IF(N(G5)=0,"",IF(ABS(N5)<=0.02,"OK","Review")) -> Review | S5: Banking - Treasury | T5: 2
A6: Banking | B6: =SUMIFS(Payroll!$I:$I,Payroll!$D:$D,$J$1,Payroll!$H:$H,"DSS",Payroll!$F:$F,"P2P*",Payroll!$K:$K,$A6) -> 1 | D6: 0 | E6: 1 | F6: =+B6+C6-D6-E6 -> 0 | G6: =+SUM(M9:M17) -> 4.0049312 | N6: =G6-F6 -> 4.0049312 | O6: =IF(N(G6)=0,"",IF(ABS(N6)<=0.02,"OK","Review")) -> Review | T6: =SUM(T3:T5) -> 10
A7: AP General | B7: =SUMIFS(Payroll!$I:$I,Payroll!$D:$D,$J$1,Payroll!$H:$H,"DSS",Payroll!$F:$F,"P2P*",Payroll!$K:$K,$A7) -> 1 | D7: 0 | F7: =+B7+C7-D7-E7 -> 1 | G7: 1 | N7: =G7-F7 -> 0 | O7: =IF(N(G7)=0,"",IF(ABS(N7)<=0.02,"OK","Review")) -> OK
A8: AP Total Clerk+TL | B8: =+SUM(B9:B17) -> 10.3125 | C8: =+SUM(C9:C17) -> 2 | D8: =+SUM(D9:D17) -> 2 | E8: =+SUM(E9:E17) -> 0.3 | F8: =+B8+C8-D8-E8 -> 10.0125 | G8: =+SUM(I9:J17) -> 38.14 | N8: =G8-F8 -> 28.1275 | O8: =IF(N(G8)=0,"",IF(ABS(N8)<=0.02,"OK","Review")) -> Review
A9: AP DE | B9: =SUMIFS(Payroll!$I:$I,Payroll!$D:$D,$J$1,Payroll!$H:$H,"DSS",Payroll!$F:$F,"P2P*",Payroll!$K:$K,$A9) -> 0 | D9: 0 | F9: =+B9+C9-D9-E9 -> 0 | G9: =SUMIFS('FTE Scorecard'!$F:$F,'FTE Scorecard'!$A:$A,"Total AP FTEs*",'FTE Scorecard'!$D:$D,TRIM(MID($A9,4,10)),'FTE Scorecard'!$E:$E,$N$1) -> 4.32 | I9: 3 | J9: 0.5 | K9: 0.18353435 | L9: 0.45 | M9: 0.18784404 | N9: =+SUM(I9:J9)-F9 -> 3.5 | O9: =IF(N(G9)=0,"",IF(ABS(N9)<=0.02,"OK","Review")) -> Review
A10: AP FR | B10: =SUMIFS(Payroll!$I:$I,Payroll!$D:$D,$J$1,Payroll!$H:$H,"DSS",Payroll!$F:$F,"P2P*",Payroll!$K:$K,$A10) -> 1.3125 | D10: 1 | F10: =+B10+C10-D10-E10 -> 0.3125 | G10: =SUMIFS('FTE Scorecard'!$F:$F,'FTE Scorecard'!$A:$A,"Total AP FTEs*",'FTE Scorecard'!$D:$D,TRIM(MID($A10,4,10)),'FTE Scorecard'!$E:$E,$N$1) -> 10.63 | I10: 7.81 | J10: 1 | K10: 0.46198217 | L10: 1.3 | M10: 0.63520642 | N10: =+(SUM(I10:J10)-F10) -> 8.4975 | O10: =IF(N(G10)=0,"",IF(ABS(N10)<=0.02,"OK","Review")) -> Review
A11: AP IB | B11: =SUMIFS(Payroll!$I:$I,Payroll!$D:$D,$J$1,Payroll!$H:$H,"DSS",Payroll!$F:$F,"P2P*",Payroll!$K:$K,$A11) -> 8 | D11: 0 | E11: 0.3 | F11: =+B11+C11-D11-E11 -> 7.7 | G11: =SUMIFS('FTE Scorecard'!$F:$F,'FTE Scorecard'!$A:$A,"Total AP FTEs*",'FTE Scorecard'!$D:$D,TRIM(MID($A11,4,10)),'FTE Scorecard'!$E:$E,$N$1) -> 10.19 | I11: 5.7 | J11: 2 | K11: 0.40377556 | L11: 1.2 | M11: 0.88979358 | N11: =+(SUM(I11:J11)-F11) -> 0 | O11: =IF(N(G11)=0,"",IF(ABS(N11)<=0.02,"OK","Review")) -> OK
A12: AP UK | B12: =SUMIFS(Payroll!$I:$I,Payroll!$D:$D,$J$1,Payroll!$H:$H,"DSS",Payroll!$F:$F,"P2P*",Payroll!$K:$K,$A12) -> 0 | C12: 1 | D12: 0 | F12: =+B12+C12-D12-E12 -> 1 | G12: =SUMIFS('FTE Scorecard'!$F:$F,'FTE Scorecard'!$A:$A,"Total AP FTEs*",'FTE Scorecard'!$D:$D,TRIM(MID($A12,4,10)),'FTE Scorecard'!$E:$E,$N$1) -> 10 | I12: 6 | J12: 0.5 | K12: 0.3408495 | L12: 2 | M12: 1.1596617 | N12: =+(SUM(I12:J14)-F12) -> 8 | O12: =IF(N(G12)=0,"",IF(ABS(N12)<=0.02,"OK","Review")) -> Review
A13: AP TMS | B13: =SUMIFS(Payroll!$I:$I,Payroll!$D:$D,$J$1,Payroll!$H:$H,"DSS",Payroll!$F:$F,"P2P*",Payroll!$K:$K,$A13) -> 0 | D13: 0 | F13: =+B13+C13-D13-E13 -> 0 | G13: =SUMIFS('FTE Scorecard'!$F:$F,'FTE Scorecard'!$A:$A,"Total AP FTEs*",'FTE Scorecard'!$D:$D,TRIM(MID($A13,4,10)),'FTE Scorecard'!$E:$E,$N$1) -> 2 | I13: 1 | J13: 0.25 | K13: 0.065547981 | L13: 0.5 | M13: 0.18043578 | N13: - | P13: Incluidos en UK
A14: AP PMS | B14: =SUMIFS(Payroll!$I:$I,Payroll!$D:$D,$J$1,Payroll!$H:$H,"DSS",Payroll!$F:$F,"P2P*",Payroll!$K:$K,$A14) -> 0 | D14: 0 | F14: =+B14+C14-D14-E14 -> 0 | G14: =SUMIFS('FTE Scorecard'!$F:$F,'FTE Scorecard'!$A:$A,"Total AP FTEs*",'FTE Scorecard'!$D:$D,TRIM(MID($A14,4,10)),'FTE Scorecard'!$E:$E,$N$1) -> 1.75 | I14: 1 | J14: 0.25 | K14: 0.065547981 | L14: 0.25 | M14: 0.18 | N14: - | P14: Incluidos en UK
A15: AP IT | B15: =SUMIFS(Payroll!$I:$I,Payroll!$D:$D,$J$1,Payroll!$H:$H,"DSS",Payroll!$F:$F,"P2P*",Payroll!$K:$K,$A15) -> 1 | D15: 0 | F15: =+B15+C15-D15-E15 -> 1 | G15: =SUMIFS('FTE Scorecard'!$F:$F,'FTE Scorecard'!$A:$A,"Total AP FTEs*",'FTE Scorecard'!$D:$D,TRIM(MID($A15,4,10)),'FTE Scorecard'!$E:$E,$N$1) -> 1.79 | I15: 1 | J15: 0.5 | K15: 0.078657577 | L15: 0.05 | M15: 0.16100917 | N15: =+(SUM(I15:J15)-F15) -> 0.5 | O15: =IF(N(G15)=0,"",IF(ABS(N15)<=0.02,"OK","Review")) -> Review
A16: AP BE | B16: =SUMIFS(Payroll!$I:$I,Payroll!$D:$D,$J$1,Payroll!$H:$H,"DSS",Payroll!$F:$F,"P2P*",Payroll!$K:$K,$A16) -> 0 | C16: 1 | D16: 0 | F16: =+B16+C16-D16-E16 -> 1 | G16: =SUMIFS('FTE Scorecard'!$F:$F,'FTE Scorecard'!$A:$A,"Total AP FTEs*",'FTE Scorecard'!$D:$D,TRIM(MID($A16,4,10)),'FTE Scorecard'!$E:$E,$N$1) -> 4.89 | I16: 3 | J16: 1 | K16: 0.20975354 | L16: 0.5 | M16: 0.18491972 | N16: =+(SUM(I16:J16)-F16) -> 3 | O16: =IF(N(G16)=0,"",IF(ABS(N16)<=0.02,"OK","Review")) -> Review
A17: AP PS | B17: =SUMIFS(Payroll!$I:$I,Payroll!$D:$D,$J$1,Payroll!$H:$H,"DSS",Payroll!$F:$F,"P2P*",Payroll!$K:$K,$A17) -> 0 | D17: 1 | F17: =+B17+C17-D17-E17 -> -1 | G17: =SUMIFS('FTE Scorecard'!$F:$F,'FTE Scorecard'!$A:$A,"Total AP FTEs*",'FTE Scorecard'!$D:$D,TRIM(MID($A17,4,10)),'FTE Scorecard'!$E:$E,$N$1) -> 4.5 | I17: 2.63 | J17: 1 | K17: 0.19035134 | L17: 0.25 | M17: 0.42606078 | N17: =+(SUM(I17:J17)-F17) -> 4.63 | O17: =IF(N(G17)=0,"",IF(ABS(N17)<=0.02,"OK","Review")) -> Review
A20: AR | B20: =SUM(B21:B23) -> 19 | C20: =+SUM(C21:C23) -> 0 | D20: =+SUM(D21:D23) -> 0 | E20: =+SUM(E21:E23) -> 0 | F20: =+B20+C20-D20-E20 -> 19 | G20: =SUMIFS('FTE Scorecard'!$F:$F,'FTE Scorecard'!$A:$A,"Total AR FTEs*",'FTE Scorecard'!$E:$E,$N$1) -> 23.1 | N20: =G20-F20 -> 4.1 | O20: =IF(N(G20)=0,"",IF(ABS(N20)<=0.02,"OK","Review")) -> Review
A21: AR Continuos improvement | B21: =SUMIFS(Payroll!$I:$I,Payroll!$D:$D,$J$1,Payroll!$H:$H,"DSS",Payroll!$F:$F,"Q2C",Payroll!$J:$J,"Mejora") -> 1 | F21: =+B21+C21-D21-E21 -> 1 | G21: 1 | N21: =G21-F21 -> 0 | O21: =IF(N(G21)=0,"",IF(ABS(N21)<=0.02,"OK","Review")) -> OK
A22: AR Banking | B22: =SUMIFS(Payroll!$I:$I,Payroll!$D:$D,$J$1,Payroll!$H:$H,"DSS",Payroll!$F:$F,"Q2C",Payroll!$G:$G,"Banking") -> 2 | F22: =+B22+C22-D22-E22 -> 2 | G22: 2 | N22: =G22-F22 -> 0 | O22: =IF(N(G22)=0,"",IF(ABS(N22)<=0.02,"OK","Review")) -> OK
A23: AR Clerk+TL | B23: =SUMIFS(Payroll!$I:$I,Payroll!$D:$D,$J$1,Payroll!$H:$H,"DSS",Payroll!$F:$F,"Q2C")-B21-B22 -> 16 | F23: =+B23+C23-D23-E23 -> 16 | G23: 16 | N23: =G23-F23 -> 0 | O23: =IF(N(G23)=0,"",IF(ABS(N23)<=0.02,"OK","Review")) -> OK
A25: R2R | B25: =SUM(B26:B28) -> 25.625 | C25: =+SUM(C26:C28) -> 1 | D25: =+SUM(D26:D28) -> 0 | E25: =+SUM(E26:E28) -> 5 | F25: =+B25+C25-D25-E25 -> 21.625 | G25: =SUMIFS('FTE Scorecard'!$F:$F,'FTE Scorecard'!$A:$A,"Total R2R*",'FTE Scorecard'!$E:$E,$N$1) -> 0 | N25: =G25-F25 -> -21.625 | O25: =IF(N(G25)=0,"",IF(ABS(N25)<=0.02,"OK","Review"))
A26: R2R Continuos improvement | B26: =SUMIFS(Payroll!$I:$I,Payroll!$D:$D,$J$1,Payroll!$H:$H,"DSS",Payroll!$F:$F,"R2R",Payroll!$J:$J,"Mejora") -> 0 | F26: =+B26+C26-D26-E26 -> 0 | G26: 0 | N26: =G26-F26 -> 0 | O26: =IF(N(G26)=0,"",IF(ABS(N26)<=0.02,"OK","Review"))
A27: R2R Banking | B27: =SUMIFS(Payroll!$I:$I,Payroll!$D:$D,$J$1,Payroll!$H:$H,"DSS",Payroll!$F:$F,"R2R",Payroll!$G:$G,"Banking") -> 2 | F27: =+B27+C27-D27-E27 -> 2 | G27: 2 | N27: =G27-F27 -> 0 | O27: =IF(N(G27)=0,"",IF(ABS(N27)<=0.02,"OK","Review")) -> OK
A28: R2R Junior+Senior | B28: =SUMIFS(Payroll!$I:$I,Payroll!$D:$D,$J$1,Payroll!$H:$H,"DSS",Payroll!$F:$F,"R2R")-B26-B27 -> 23.625 | C28: 1 | E28: 5 | F28: =+B28+C28-D28-E28 -> 19.625 | G28: 18.75 | N28: =G28-F28 -> -0.875 | O28: =IF(N(G28)=0,"",IF(ABS(N28)<=0.02,"OK","Review")) -> Review
A30: HR | B30: =SUMIFS(Payroll!$I:$I,Payroll!$D:$D,$J$1,Payroll!$H:$H,"DSS",Payroll!$F:$F,"HR") -> 1 | F30: =+B30+C30-D30-E30 -> 1 | G30: 1 | N30: =G30-F30 -> 0 | O30: =IF(N(G30)=0,"",IF(ABS(N30)<=0.02,"OK","Review")) -> OK
A32: MD | B32: =SUMIFS(Payroll!$I:$I,Payroll!$D:$D,$J$1,Payroll!$H:$H,"DSS",Payroll!$F:$F,"DM") -> 3 | F32: =+B32+C32-D32-E32 -> 3 | G32: 3 | N32: =G32-F32 -> 0 | O32: =IF(N(G32)=0,"",IF(ABS(N32)<=0.02,"OK","Review")) -> OK
A34: Subtotal (processes above) | B34: =B3+B20+B25+B30+B32 -> 62.9375 | C34: =C3+C20+C25+C30+C32 -> 3 | D34: =D3+D20+D25+D30+D32 -> 3 | E34: =E3+E20+E25+E30+E32 -> 6.8 | F34: =+B34+C34-D34-E34 -> 56.1375 | G34: =+G3+G20+G25+G30+G32 -> 77.17 | N34: =G34-F34 -> 21.0325 | O34: =IF(N(G34)=0,"",IF(ABS(N34)<=0.02,"OK","Review")) -> Review
A35: Out of scope (OoS) | B35: =SUMIFS(Payroll!$I:$I,Payroll!$D:$D,$J$1,Payroll!$H:$H,"DSS",Payroll!$F:$F,"OoS") -> 0
A36: TOTAL PAYROLL (DSS) | B36: =SUMIFS(Payroll!$I:$I,Payroll!$D:$D,$J$1,Payroll!$H:$H,"DSS") -> 104.375
A37: Unexplained difference | B37: =B36-B34-B35 -> 41.4375 | O37: =IF(ABS(B37)<=0.02,"OK","Review") -> Review
A39: ="Payroll rows in use: "&TEXT(COUNTA(Payroll!$D:$D)-1,"#,##0")&IF(COUNTA(Payroll!$D:$D)-1>4999," ⚠ Beyond row 5000: drag column K of Payroll further down."," · DSS "&TEXT(SUMIFS(Payroll!$I:$I,Payroll!$D:$D,$J$1,Payroll!$H:$H,"DSS"),"#,##0.00")&" + IP "&TEXT(SUMIFS(Payroll!$I:$I,Payroll!$D:$D,$J$1,Payroll!$H:$H,"IP"),"#,##0.00")&" + other business "&TEXT(SUMIFS(Payroll!$I:$I,Payroll!$D:$D,$J$1)-SUMIFS(Payroll!$I:$I,Payroll!$D:$D,$J$1,Payroll!$H:$H,"DSS")-SUMIFS(Payroll!$I:$I,Payroll!$D:$D,$J$1,Payroll!$H:$H,"IP"),"#,##0.00")&" = "&TEXT(SUMIFS(Payroll!$I:$I,Payroll!$D:$D,$J$1),"#,##0.00")&" · unmapped: "&TEXT(COUNTIF(Payroll!$K:$K,"(unmapped)"),"0")) -> Payroll rows in use: 180,0 · DSS 104,37500 + IP 65,47500 + other business 3,000 = 172,85000 · unmapped: 0

Sheet IP Reconciliation
A1: IP RECONCILIATION · Payroll vs Scorecard | D1: Period: | F1: AP09 | G1: Year: | H1: 2026 | I1: SC date: | J1: ="01/"&RIGHT($F$1,2)&"/"&$H$1 -> 01/09/2026
A2: Item | B2: Payroll FTE | C2: Vacancy | D2: Sick leave | E2: Adjustment | F2: FTE Real | G2: FTE Scorecard | H2: Difference | I2: Status | J2: Comments
A3: P2P | B3: =SUM(B4:B9) -> 23.8 | F3: =+B3+C3-D3-E3 -> 23.8 | G3: =+B3 -> 23.8 | H3: =+G3-F3 -> 0 | I3: =IF(N(G3)=0,"",IF(ABS(H3)<=0.02,"OK","Review")) -> OK
A4: AP IB | B4: =SUMIFS(Payroll!$I:$I,Payroll!$D:$D,$F$1,Payroll!$H:$H,"IP",Payroll!$F:$F,"P2P*",Payroll!$K:$K,$A4) -> 7 | F4: =+B4+C4-D4-E4 -> 7 | G4: =+B4 -> 7 | H4: =+G4-F4 -> 0 | I4: =IF(N(G4)=0,"",IF(ABS(H4)<=0.02,"OK","Review")) -> OK
A5: AP FR | B5: =SUMIFS(Payroll!$I:$I,Payroll!$D:$D,$F$1,Payroll!$H:$H,"IP",Payroll!$F:$F,"P2P*",Payroll!$K:$K,$A5) -> 1.8 | F5: =+B5+C5-D5-E5 -> 1.8 | G5: =+B5 -> 1.8 | H5: =+G5-F5 -> 0 | I5: =IF(N(G5)=0,"",IF(ABS(H5)<=0.02,"OK","Review")) -> OK
A6: AP IT | B6: =SUMIFS(Payroll!$I:$I,Payroll!$D:$D,$F$1,Payroll!$H:$H,"IP",Payroll!$F:$F,"P2P*",Payroll!$K:$K,$A6) -> 4 | F6: =+B6+C6-D6-E6 -> 4 | G6: =+B6 -> 4 | H6: =+G6-F6 -> 0 | I6: =IF(N(G6)=0,"",IF(ABS(H6)<=0.02,"OK","Review")) -> OK
A7: AP MA | B7: =SUMIFS(Payroll!$I:$I,Payroll!$D:$D,$F$1,Payroll!$H:$H,"IP",Payroll!$F:$F,"P2P*",Payroll!$K:$K,$A7) -> 7 | F7: =+B7+C7-D7-E7 -> 7 | G7: =+B7 -> 7 | H7: =+G7-F7 -> 0 | I7: =IF(N(G7)=0,"",IF(ABS(H7)<=0.02,"OK","Review")) -> OK
A8: AP Help Desk | B8: =SUMIFS(Payroll!$I:$I,Payroll!$D:$D,$F$1,Payroll!$H:$H,"IP",Payroll!$F:$F,"P2P*",Payroll!$K:$K,$A8) -> 1 | F8: =+B8+C8-D8-E8 -> 1 | G8: =+B8 -> 1 | H8: =+G8-F8 -> 0 | I8: =IF(N(G8)=0,"",IF(ABS(H8)<=0.02,"OK","Review")) -> OK
A9: Banking | B9: =SUMIFS(Payroll!$I:$I,Payroll!$D:$D,$F$1,Payroll!$H:$H,"IP",Payroll!$F:$F,"P2P*",Payroll!$K:$K,$A9) -> 3 | F9: =+B9+C9-D9-E9 -> 3 | G9: =+B9 -> 3 | H9: =+G9-F9 -> 0 | I9: =IF(N(G9)=0,"",IF(ABS(H9)<=0.02,"OK","Review")) -> OK
A11: AR | B11: =SUM(B12:B16) -> 18.675 | F11: =+B11+C11-D11-E11 -> 18.675 | G11: =+B11 -> 18.675 | H11: =+G11-F11 -> 0 | I11: =IF(N(G11)=0,"",IF(ABS(H11)<=0.02,"OK","Review")) -> OK
A12: AR IB | B12: =SUMIFS(Payroll!$I:$I,Payroll!$D:$D,$F$1,Payroll!$H:$H,"IP",Payroll!$K:$K,$A12) -> 13.675 | F12: =+B12+C12-D12-E12 -> 13.675 | G12: =+B12 -> 13.675 | H12: =+G12-F12 -> 0 | I12: =IF(N(G12)=0,"",IF(ABS(H12)<=0.02,"OK","Review")) -> OK
A13: AR FR | B13: =SUMIFS(Payroll!$I:$I,Payroll!$D:$D,$F$1,Payroll!$H:$H,"IP",Payroll!$K:$K,$A13) -> 0 | F13: =+B13+C13-D13-E13 -> 0 | G13: =+B13 -> 0 | H13: =+G13-F13 -> 0 | I13: =IF(N(G13)=0,"",IF(ABS(H13)<=0.02,"OK","Review"))
A14: AR IT | B14: =SUMIFS(Payroll!$I:$I,Payroll!$D:$D,$F$1,Payroll!$H:$H,"IP",Payroll!$K:$K,$A14) -> 1 | F14: =+B14+C14-D14-E14 -> 1 | G14: =+B14 -> 1 | H14: =+G14-F14 -> 0 | I14: =IF(N(G14)=0,"",IF(ABS(H14)<=0.02,"OK","Review")) -> OK
A15: AR MA | B15: =SUMIFS(Payroll!$I:$I,Payroll!$D:$D,$F$1,Payroll!$H:$H,"IP",Payroll!$K:$K,$A15) -> 0 | F15: =+B15+C15-D15-E15 -> 0 | G15: =+B15 -> 0 | H15: =+G15-F15 -> 0 | I15: =IF(N(G15)=0,"",IF(ABS(H15)<=0.02,"OK","Review"))
A16: AR Banking | B16: =SUMIFS(Payroll!$I:$I,Payroll!$D:$D,$F$1,Payroll!$H:$H,"IP",Payroll!$K:$K,$A16) -> 4 | F16: =+B16+C16-D16-E16 -> 4 | G16: =+B16 -> 4 | H16: =+G16-F16 -> 0 | I16: =IF(N(G16)=0,"",IF(ABS(H16)<=0.02,"OK","Review")) -> OK
A18: R2R | B18: =SUM(B19:B23) -> 21 | F18: =+B18+C18-D18-E18 -> 21 | G18: =+B18 -> 21 | H18: =+G18-F18 -> 0 | I18: =IF(N(G18)=0,"",IF(ABS(H18)<=0.02,"OK","Review")) -> OK
A19: R2R IB | B19: =SUMIFS(Payroll!$I:$I,Payroll!$D:$D,$F$1,Payroll!$H:$H,"IP",Payroll!$K:$K,$A19) -> 19 | F19: =+B19+C19-D19-E19 -> 19 | G19: =+B19 -> 19 | H19: =+G19-F19 -> 0 | I19: =IF(N(G19)=0,"",IF(ABS(H19)<=0.02,"OK","Review")) -> OK
A20: R2R FR | B20: =SUMIFS(Payroll!$I:$I,Payroll!$D:$D,$F$1,Payroll!$H:$H,"IP",Payroll!$K:$K,$A20) -> 0 | F20: =+B20+C20-D20-E20 -> 0 | G20: =+B20 -> 0 | H20: =+G20-F20 -> 0 | I20: =IF(N(G20)=0,"",IF(ABS(H20)<=0.02,"OK","Review"))
A21: R2R IT | B21: =SUMIFS(Payroll!$I:$I,Payroll!$D:$D,$F$1,Payroll!$H:$H,"IP",Payroll!$K:$K,$A21) -> 0 | F21: =+B21+C21-D21-E21 -> 0 | G21: =+B21 -> 0 | H21: =+G21-F21 -> 0 | I21: =IF(N(G21)=0,"",IF(ABS(H21)<=0.02,"OK","Review"))
A22: R2R MA | B22: =SUMIFS(Payroll!$I:$I,Payroll!$D:$D,$F$1,Payroll!$H:$H,"IP",Payroll!$K:$K,$A22) -> 0 | F22: =+B22+C22-D22-E22 -> 0 | G22: =+B22 -> 0 | H22: =+G22-F22 -> 0 | I22: =IF(N(G22)=0,"",IF(ABS(H22)<=0.02,"OK","Review"))
A23: R2R Banking | B23: =SUMIFS(Payroll!$I:$I,Payroll!$D:$D,$F$1,Payroll!$H:$H,"IP",Payroll!$K:$K,$A23) -> 2 | F23: =+B23+C23-D23-E23 -> 2 | G23: =+B23 -> 2 | H23: =+G23-F23 -> 0 | I23: =IF(N(G23)=0,"",IF(ABS(H23)<=0.02,"OK","Review")) -> OK
A25: HR | B25: =SUMIFS(Payroll!$I:$I,Payroll!$D:$D,$F$1,Payroll!$H:$H,"IP",Payroll!$F:$F,"HR") -> 1 | F25: =+B25+C25-D25-E25 -> 1 | G25: =+B25 -> 1 | H25: =+G25-B25 -> 0 | I25: =IF(N(G25)=0,"",IF(ABS(H25)<=0.02,"OK","Review")) -> OK
A27: MD | B27: =SUMIFS(Payroll!$I:$I,Payroll!$D:$D,$F$1,Payroll!$H:$H,"IP",Payroll!$F:$F,"DM") -> 0 | F27: =+B27+C27-D27-E27 -> 0 | G27: =+B27 -> 0 | H27: =+G27-B27 -> 0 | I27: =IF(N(G27)=0,"",IF(ABS(H27)<=0.02,"OK","Review"))
A29: Subtotal (processes above) | B29: =B3+B11+B18+B25+B27 -> 64.475 | F29: =F3+F11+F18+F25+F27 -> 64.475 | G29: =G3+G11+G18+G25+G27 -> 64.475 | H29: =+G29-B29 -> 0 | I29: =IF(N(G29)=0,"",IF(ABS(H29)<=0.02,"OK","Review")) -> OK
A30: Out of scope (OoS) | B30: =SUMIFS(Payroll!$I:$I,Payroll!$D:$D,$F$1,Payroll!$H:$H,"IP",Payroll!$F:$F,"OoS") -> 0
A31: TOTAL PAYROLL (IP) | B31: =SUMIFS(Payroll!$I:$I,Payroll!$D:$D,$F$1,Payroll!$H:$H,"IP") -> 65.475
A32: Unexplained difference | B32: =B31-B29-B30 -> 1 | I32: =IF(ABS(B32)<=0.02,"OK","Review") -> Review
A34: ="Payroll "&$F$1&" · DSS "&TEXT(SUMIFS(Payroll!$I:$I,Payroll!$D:$D,$F$1,Payroll!$H:$H,"DSS"),"#,##0.00")&" + IP "&TEXT(SUMIFS(Payroll!$I:$I,Payroll!$D:$D,$F$1,Payroll!$H:$H,"IP"),"#,##0.00")&" + other business "&TEXT(SUMIFS(Payroll!$I:$I,Payroll!$D:$D,$F$1)-SUMIFS(Payroll!$I:$I,Payroll!$D:$D,$F$1,Payroll!$H:$H,"DSS")-SUMIFS(Payroll!$I:$I,Payroll!$D:$D,$F$1,Payroll!$H:$H,"IP"),"#,##0.00")&" = "&TEXT(SUMIFS(Payroll!$I:$I,Payroll!$D:$D,$F$1),"#,##0.00")&" · The IP Scorecard is not available yet: column F is a manual entry." -> Payroll AP09 · DSS 104,37500 + IP 65,47500 + other business 3,000 = 172,85000 · The IP Scorecard is not available yet: column F is a manual entry.

Sheet FTE Scorecard
A1: Definitions | B1: Scorecard Division | C1: Scorecard País | D1: Equipo | E1: Fecha | F1: FTE
A2: Total AP FTEs (all, incl. payments, team leaders, manager) | B2: DE_Pack | C2: DE | D2: DE | E2: 01/09/2026 | F2: 4.32
A3: Total AP FTEs (all, incl. payments, team leaders, manager) | B3: FR_Qualiac | C3: FR | D3: FR | E3: 01/09/2026 | F3: 9.03
A4: Total AP FTEs (all, incl. payments, team leaders, manager) | B4: IT_Paper | C4: IT | D4: IT | E4: 01/09/2026 | F4: 1.79
A5: Total AP FTEs (all, incl. payments, team leaders, manager) | B5: BE_Pack | C5: BE | D5: BE | E5: 01/09/2026 | F5: 2.01
A6: Total AP FTEs (all, incl. payments, team leaders, manager) | B6: NL_Pack | C6: BE | D6: BE | E6: 01/09/2026 | F6: 2.88
A7: Total AP FTEs (all, incl. payments, team leaders, manager) | B7: NL_PMS | C7: PMS | D7: PMS | E7: 01/09/2026 | F7: 1.75
A8: Total AP FTEs (all, incl. payments, team leaders, manager) | B8: UK_TMS | C8: TMS | D8: TMS | E8: 01/09/2026 | F8: 2
A9: Total AP FTEs (all, incl. payments, team leaders, manager) | B9: NL_Paper | C9: PS | D9: PS | E9: 01/09/2026 | F9: 4.5
A10: Total AP FTEs (all, incl. payments, team leaders, manager) | B10: UK_Pack | C10: UK | D10: UK | E10: 01/09/2026 | F10: 5.49
A11: Total AP FTEs (all, incl. payments, team leaders, manager) | B11: UK_Paper | C11: UK | D11: UK | E11: 01/09/2026 | F11: 1.88
A12: Total AP FTEs (all, incl. payments, team leaders, manager) | B12: UK_PLC | C12: UK | D12: UK | E12: 01/09/2026 | F12: 0.43
A13: Total AP FTEs (all, incl. payments, team leaders, manager) | B13: UK_Recycling | C13: UK | D13: UK | E13: 01/09/2026 | F13: 2.2
... A26: Total AP FTEs (all, incl. payments, team leaders, manager) | B26: Paper Iberia | C26: - | D26: IB | E26: 01/09/2026 | F26: 3.41006

Sheet Payroll
A1: Cost centre | B1: Employee no. | C1: Employee name | D1: Period | E1: Calendar year | F1: Process | G1: Sub-process | H1: Business | I1: FTE | J1: Team | K1: Category
A2: ES1101 | B2: PT1 | C2: Ines Martins | D2: AP09 | E2: 2026 | F2: Q2C | H2: DSS | I2: 1 | J2: Iberia | K2: =IF($D2="","",IFERROR(INDEX(Mapping!$H$3:$H$32,MATCH($B2,Mapping!$G$3:$G$32,0)),IF(LEFT($F2,3)="P2P",IFERROR(INDEX(Mapping!$E$3:$E$6,MATCH($G2,Mapping!$D$3:$D$6,0)),IFERROR(INDEX(Mapping!$B$3:$B$13,MATCH($J2,Mapping!$A$3:$A$13,0)),"(unmapped)")),IFERROR(INDEX(Mapping!$B$17:$B$22,MATCH($F2,Mapping!$A$17:$A$22,0)),$F2)&" "&IF($G2="Banking","Banking",IFERROR(INDEX(Mapping!$E$17:$E$28,MATCH($J2,Mapping!$D$17:$D$28,0)),"(unmapped)"))))) -> AR IB
A3: ES1101 | B3: PT2 | C3: Claudia Couto | D3: AP09 | E3: 2026 | F3: Q2C | H3: DSS | I3: 1 | J3: Iberia | K3: =IF($D3="","",IFERROR(INDEX(Mapping!$H$3:$H$32,MATCH($B3,Mapping!$G$3:$G$32,0)),IF(LEFT($F3,3)="P2P",IFERROR(INDEX(Mapping!$E$3:$E$6,MATCH($G3,Mapping!$D$3:$D$6,0)),IFERROR(INDEX(Mapping!$B$3:$B$13,MATCH($J3,Mapping!$A$3:$A$13,0)),"(unmapped)")),IFERROR(INDEX(Mapping!$B$17:$B$22,MATCH($F3,Mapping!$A$17:$A$22,0)),$F3)&" "&IF($G3="Banking","Banking",IFERROR(INDEX(Mapping!$E$17:$E$28,MATCH($J3,Mapping!$D$17:$D$28,0)),"(unmapped)"))))) -> AR IB
A4: 10000570 | B4: 100122 | C4: Yolanda Lazaro Esteban | D4: AP09 | E4: 2026 | F4: P2P | H4: DSS | I4: 1 | J4: Iberia | K4: =IF($D4="","",IFERROR(INDEX(Mapping!$H$3:$H$32,MATCH($B4,Mapping!$G$3:$G$32,0)),IF(LEFT($F4,3)="P2P",IFERROR(INDEX(Mapping!$E$3:$E$6,MATCH($G4,Mapping!$D$3:$D$6,0)),IFERROR(INDEX(Mapping!$B$3:$B$13,MATCH($J4,Mapping!$A$3:$A$13,0)),"(unmapped)")),IFERROR(INDEX(Mapping!$B$17:$B$22,MATCH($F4,Mapping!$A$17:$A$22,0)),$F4)&" "&IF($G4="Banking","Banking",IFERROR(INDEX(Mapping!$E$17:$E$28,MATCH($J4,Mapping!$D$17:$D$28,0)),"(unmapped)"))))) -> AP IB
A5: 10000570 | B5: 100282 | C5: BLANCO TIJERO, RITA | D5: AP09 | E5: 2026 | F5: P2P | H5: DSS | I5: 1 | J5: Iberia | K5: =IF($D5="","",IFERROR(INDEX(Mapping!$H$3:$H$32,MATCH($B5,Mapping!$G$3:$G$32,0)),IF(LEFT($F5,3)="P2P",IFERROR(INDEX(Mapping!$E$3:$E$6,MATCH($G5,Mapping!$D$3:$D$6,0)),IFERROR(INDEX(Mapping!$B$3:$B$13,MATCH($J5,Mapping!$A$3:$A$13,0)),"(unmapped)")),IFERROR(INDEX(Mapping!$B$17:$B$22,MATCH($F5,Mapping!$A$17:$A$22,0)),$F5)&" "&IF($G5="Banking","Banking",IFERROR(INDEX(Mapping!$E$17:$E$28,MATCH($J5,Mapping!$D$17:$D$28,0)),"(unmapped)"))))) -> AP IB
A6: 10000570 | B6: 100386 | C6: RODRIGUEZ VAZQUEZ, TERESA | D6: AP09 | E6: 2026 | F6: Q2C | H6: DSS | I6: 1 | J6: Iberia | K6: =IF($D6="","",IFERROR(INDEX(Mapping!$H$3:$H$32,MATCH($B6,Mapping!$G$3:$G$32,0)),IF(LEFT($F6,3)="P2P",IFERROR(INDEX(Mapping!$E$3:$E$6,MATCH($G6,Mapping!$D$3:$D$6,0)),IFERROR(INDEX(Mapping!$B$3:$B$13,MATCH($J6,Mapping!$A$3:$A$13,0)),"(unmapped)")),IFERROR(INDEX(Mapping!$B$17:$B$22,MATCH($F6,Mapping!$A$17:$A$22,0)),$F6)&" "&IF($G6="Banking","Banking",IFERROR(INDEX(Mapping!$E$17:$E$28,MATCH($J6,Mapping!$D$17:$D$28,0)),"(unmapped)"))))) -> AR IB
A7: 10000570 | B7: 100487 | C7: ALFONSO DEL VALLE, ALICIA | D7: AP09 | E7: 2026 | F7: P2P Vuelta | H7: DSS | I7: 1 | J7: FR | K7: =IF($D7="","",IFERROR(INDEX(Mapping!$H$3:$H$32,MATCH($B7,Mapping!$G$3:$G$32,0)),IF(LEFT($F7,3)="P2P",IFERROR(INDEX(Mapping!$E$3:$E$6,MATCH($G7,Mapping!$D$3:$D$6,0)),IFERROR(INDEX(Mapping!$B$3:$B$13,MATCH($J7,Mapping!$A$3:$A$13,0)),"(unmapped)")),IFERROR(INDEX(Mapping!$B$17:$B$22,MATCH($F7,Mapping!$A$17:$A$22,0)),$F7)&" "&IF($G7="Banking","Banking",IFERROR(INDEX(Mapping!$E$17:$E$28,MATCH($J7,Mapping!$D$17:$D$28,0)),"(unmapped)"))))) -> P2P Vuelta FR
A8: 10000570 | B8: 100511 | C8: INGELMO GOMEZ MARCOS | D8: AP09 | E8: 2026 | F8: Q2C | H8: DSS | I8: 1 | J8: Iberia | K8: =IF($D8="","",IFERROR(INDEX(Mapping!$H$3:$H$32,MATCH($B8,Mapping!$G$3:$G$32,0)),IF(LEFT($F8,3)="P2P",IFERROR(INDEX(Mapping!$E$3:$E$6,MATCH($G8,Mapping!$D$3:$D$6,0)),IFERROR(INDEX(Mapping!$B$3:$B$13,MATCH($J8,Mapping!$A$3:$A$13,0)),"(unmapped)")),IFERROR(INDEX(Mapping!$B$17:$B$22,MATCH($F8,Mapping!$A$17:$A$22,0)),$F8)&" "&IF($G8="Banking","Banking",IFERROR(INDEX(Mapping!$E$17:$E$28,MATCH($J8,Mapping!$D$17:$D$28,0)),"(unmapped)"))))) -> AR IB
A9: 10000570 | B9: 100839 | C9: CALLEJA GUERRA, JULIO JOSE | D9: AP09 | E9: 2026 | F9: R2R | G9: Banking | H9: IP | I9: 1 | J9: Iberia | K9: =IF($D9="","",IFERROR(INDEX(Mapping!$H$3:$H$32,MATCH($B9,Mapping!$G$3:$G$32,0)),IF(LEFT($F9,3)="P2P",IFERROR(INDEX(Mapping!$E$3:$E$6,MATCH($G9,Mapping!$D$3:$D$6,0)),IFERROR(INDEX(Mapping!$B$3:$B$13,MATCH($J9,Mapping!$A$3:$A$13,0)),"(unmapped)")),IFERROR(INDEX(Mapping!$B$17:$B$22,MATCH($F9,Mapping!$A$17:$A$22,0)),$F9)&" "&IF($G9="Banking","Banking",IFERROR(INDEX(Mapping!$E$17:$E$28,MATCH($J9,Mapping!$D$17:$D$28,0)),"(unmapped)"))))) -> R2R Banking
A10: 10000570 | B10: 100958 | C10: CAMARERO CARRION, CRISTINA | D10: AP09 | E10: 2026 | F10: R2R | H10: DSS | I10: 1 | J10: Kunheim | K10: =IF($D10="","",IFERROR(INDEX(Mapping!$H$3:$H$32,MATCH($B10,Mapping!$G$3:$G$32,0)),IF(LEFT($F10,3)="P2P",IFERROR(INDEX(Mapping!$E$3:$E$6,MATCH($G10,Mapping!$D$3:$D$6,0)),IFERROR(INDEX(Mapping!$B$3:$B$13,MATCH($J10,Mapping!$A$3:$A$13,0)),"(unmapped)")),IFERROR(INDEX(Mapping!$B$17:$B$22,MATCH($F10,Mapping!$A$17:$A$22,0)),$F10)&" "&IF($G10="Banking","Banking",IFERROR(INDEX(Mapping!$E$17:$E$28,MATCH($J10,Mapping!$D$17:$D$28,0)),"(unmapped)"))))) -> R2R Kunheim
A11: 10000570 | B11: 100980 | C11: DIEZ GONZALEZ, BELEN | D11: AP09 | E11: 2026 | F11: R2R | H11: DSS | I11: 0.875 | J11: Iberia | K11: =IF($D11="","",IFERROR(INDEX(Mapping!$H$3:$H$32,MATCH($B11,Mapping!$G$3:$G$32,0)),IF(LEFT($F11,3)="P2P",IFERROR(INDEX(Mapping!$E$3:$E$6,MATCH($G11,Mapping!$D$3:$D$6,0)),IFERROR(INDEX(Mapping!$B$3:$B$13,MATCH($J11,Mapping!$A$3:$A$13,0)),"(unmapped)")),IFERROR(INDEX(Mapping!$B$17:$B$22,MATCH($F11,Mapping!$A$17:$A$22,0)),$F11)&" "&IF($G11="Banking","Banking",IFERROR(INDEX(Mapping!$E$17:$E$28,MATCH($J11,Mapping!$D$17:$D$28,0)),"(unmapped)"))))) -> R2R IB
A12: 10000570 | B12: 101011 | C12: BUJIDOS CHACON, NEREA | D12: AP09 | E12: 2026 | F12: P2P | H12: IP | I12: 1 | J12: Iberia | K12: =IF($D12="","",IFERROR(INDEX(Mapping!$H$3:$H$32,MATCH($B12,Mapping!$G$3:$G$32,0)),IF(LEFT($F12,3)="P2P",IFERROR(INDEX(Mapping!$E$3:$E$6,MATCH($G12,Mapping!$D$3:$D$6,0)),IFERROR(INDEX(Mapping!$B$3:$B$13,MATCH($J12,Mapping!$A$3:$A$13,0)),"(unmapped)")),IFERROR(INDEX(Mapping!$B$17:$B$22,MATCH($F12,Mapping!$A$17:$A$22,0)),$F12)&" "&IF($G12="Banking","Banking",IFERROR(INDEX(Mapping!$E$17:$E$28,MATCH($J12,Mapping!$D$17:$D$28,0)),"(unmapped)"))))) -> AP IB
A13: 10000570 | B13: 101019 | C13: MERINO LOPEZ, VICTOR | D13: AP09 | E13: 2026 | F13: R2R | H13: IP | I13: 1 | J13: Iberia | K13: =IF($D13="","",IFERROR(INDEX(Mapping!$H$3:$H$32,MATCH($B13,Mapping!$G$3:$G$32,0)),IF(LEFT($F13,3)="P2P",IFERROR(INDEX(Mapping!$E$3:$E$6,MATCH($G13,Mapping!$D$3:$D$6,0)),IFERROR(INDEX(Mapping!$B$3:$B$13,MATCH($J13,Mapping!$A$3:$A$13,0)),"(unmapped)")),IFERROR(INDEX(Mapping!$B$17:$B$22,MATCH($F13,Mapping!$A$17:$A$22,0)),$F13)&" "&IF($G13="Banking","Banking",IFERROR(INDEX(Mapping!$E$17:$E$28,MATCH($J13,Mapping!$D$17:$D$28,0)),"(unmapped)"))))) -> R2R IB
A14: 10000570 | B14: 101034 | C14: SULLIVAN, EVE KATHLEEN | D14: AP09 | E14: 2026 | F14: P2P | H14: DSS | I14: 1 | J14: General | K14: =IF($D14="","",IFERROR(INDEX(Mapping!$H$3:$H$32,MATCH($B14,Mapping!$G$3:$G$32,0)),IF(LEFT($F14,3)="P2P",IFERROR(INDEX(Mapping!$E$3:$E$6,MATCH($G14,Mapping!$D$3:$D$6,0)),IFERROR(INDEX(Mapping!$B$3:$B$13,MATCH($J14,Mapping!$A$3:$A$13,0)),"(unmapped)")),IFERROR(INDEX(Mapping!$B$17:$B$22,MATCH($F14,Mapping!$A$17:$A$22,0)),$F14)&" "&IF($G14="Banking","Banking",IFERROR(INDEX(Mapping!$E$17:$E$28,MATCH($J14,Mapping!$D$17:$D$28,0)),"(unmapped)"))))) -> AP General
A15: 10000570 | B15: 101036 | C15: PRIETO ROJO, MARIA NATALIA | D15: AP09 | E15: 2026 | F15: P2P | G15: Helpdesk | H15: IP | I15: 1 | J15: Iberia | K15: =IF($D15="","",IFERROR(INDEX(Mapping!$H$3:$H$32,MATCH($B15,Mapping!$G$3:$G$32,0)),IF(LEFT($F15,3)="P2P",IFERROR(INDEX(Mapping!$E$3:$E$6,MATCH($G15,Mapping!$D$3:$D$6,0)),IFERROR(INDEX(Mapping!$B$3:$B$13,MATCH($J15,Mapping!$A$3:$A$13,0)),"(unmapped)")),IFERROR(INDEX(Mapping!$B$17:$B$22,MATCH($F15,Mapping!$A$17:$A$22,0)),$F15)&" "&IF($G15="Banking","Banking",IFERROR(INDEX(Mapping!$E$17:$E$28,MATCH($J15,Mapping!$D$17:$D$28,0)),"(unmapped)"))))) -> AP Help Desk
A16: 10000570 | B16: 101047 | C16: ESCAÑO CASTAÑO, LAURA | D16: AP09 | E16: 2026 | F16: P2P | H16: DSS | I16: 1 | J16: Iberia | K16: =IF($D16="","",IFERROR(INDEX(Mapping!$H$3:$H$32,MATCH($B16,Mapping!$G$3:$G$32,0)),IF(LEFT($F16,3)="P2P",IFERROR(INDEX(Mapping!$E$3:$E$6,MATCH($G16,Mapping!$D$3:$D$6,0)),IFERROR(INDEX(Mapping!$B$3:$B$13,MATCH($J16,Mapping!$A$3:$A$13,0)),"(unmapped)")),IFERROR(INDEX(Mapping!$B$17:$B$22,MATCH($F16,Mapping!$A$17:$A$22,0)),$F16)&" "&IF($G16="Banking","Banking",IFERROR(INDEX(Mapping!$E$17:$E$28,MATCH($J16,Mapping!$D$17:$D$28,0)),"(unmapped)"))))) -> AP IB
A17: 10000570 | B17: 101048 | C17: VARELA RICO, CRISTINA | D17: AP09 | E17: 2026 | F17: R2R | H17: DSS | I17: 1 | J17: Iberia | K17: =IF($D17="","",IFERROR(INDEX(Mapping!$H$3:$H$32,MATCH($B17,Mapping!$G$3:$G$32,0)),IF(LEFT($F17,3)="P2P",IFERROR(INDEX(Mapping!$E$3:$E$6,MATCH($G17,Mapping!$D$3:$D$6,0)),IFERROR(INDEX(Mapping!$B$3:$B$13,MATCH($J17,Mapping!$A$3:$A$13,0)),"(unmapped)")),IFERROR(INDEX(Mapping!$B$17:$B$22,MATCH($F17,Mapping!$A$17:$A$22,0)),$F17)&" "&IF($G17="Banking","Banking",IFERROR(INDEX(Mapping!$E$17:$E$28,MATCH($J17,Mapping!$D$17:$D$28,0)),"(unmapped)"))))) -> R2R IB
A18: 10000570 | B18: 101307 | C18: TORRES BARRIENTOS, OLGA PATRICIA | D18: AP09 | E18: 2026 | F18: R2R | H18: DSS | I18: 0.875 | J18: Iberia | K18: =IF($D18="","",IFERROR(INDEX(Mapping!$H$3:$H$32,MATCH($B18,Mapping!$G$3:$G$32,0)),IF(LEFT($F18,3)="P2P",IFERROR(INDEX(Mapping!$E$3:$E$6,MATCH($G18,Mapping!$D$3:$D$6,0)),IFERROR(INDEX(Mapping!$B$3:$B$13,MATCH($J18,Mapping!$A$3:$A$13,0)),"(unmapped)")),IFERROR(INDEX(Mapping!$B$17:$B$22,MATCH($F18,Mapping!$A$17:$A$22,0)),$F18)&" "&IF($G18="Banking","Banking",IFERROR(INDEX(Mapping!$E$17:$E$28,MATCH($J18,Mapping!$D$17:$D$28,0)),"(unmapped)"))))) -> R2R IB
A19: ES1101 | B19: 101193 | C19: ANGELA ESCOBAR BARBOSA | D19: AP09 | E19: 2026 | F19: P2P | H19: DSS | I19: 1 | J19: Mejora | K19: =IF($D19="","",IFERROR(INDEX(Mapping!$H$3:$H$32,MATCH($B19,Mapping!$G$3:$G$32,0)),IF(LEFT($F19,3)="P2P",IFERROR(INDEX(Mapping!$E$3:$E$6,MATCH($G19,Mapping!$D$3:$D$6,0)),IFERROR(INDEX(Mapping!$B$3:$B$13,MATCH($J19,Mapping!$A$3:$A$13,0)),"(unmapped)")),IFERROR(INDEX(Mapping!$B$17:$B$22,MATCH($F19,Mapping!$A$17:$A$22,0)),$F19)&" "&IF($G19="Banking","Banking",IFERROR(INDEX(Mapping!$E$17:$E$28,MATCH($J19,Mapping!$D$17:$D$28,0)),"(unmapped)"))))) -> AP Continuos improvement
A20: ES1101 | B20: 101409 | C20: BRUNO TIAGO FERRO MARTINS | D20: AP09 | E20: 2026 | F20: DM | H20: DSS | I20: 1 | J20: Iberia | K20: =IF($D20="","",IFERROR(INDEX(Mapping!$H$3:$H$32,MATCH($B20,Mapping!$G$3:$G$32,0)),IF(LEFT($F20,3)="P2P",IFERROR(INDEX(Mapping!$E$3:$E$6,MATCH($G20,Mapping!$D$3:$D$6,0)),IFERROR(INDEX(Mapping!$B$3:$B$13,MATCH($J20,Mapping!$A$3:$A$13,0)),"(unmapped)")),IFERROR(INDEX(Mapping!$B$17:$B$22,MATCH($F20,Mapping!$A$17:$A$22,0)),$F20)&" "&IF($G20="Banking","Banking",IFERROR(INDEX(Mapping!$E$17:$E$28,MATCH($J20,Mapping!$D$17:$D$28,0)),"(unmapped)"))))) -> MD IB
A21: ES1101 | B21: 101414 | C21: ZOILO GIL PEREZ | D21: AP09 | E21: 2026 | F21: Q2C | H21: DSS | I21: 1 | J21: Iberia | K21: =IF($D21="","",IFERROR(INDEX(Mapping!$H$3:$H$32,MATCH($B21,Mapping!$G$3:$G$32,0)),IF(LEFT($F21,3)="P2P",IFERROR(INDEX(Mapping!$E$3:$E$6,MATCH($G21,Mapping!$D$3:$D$6,0)),IFERROR(INDEX(Mapping!$B$3:$B$13,MATCH($J21,Mapping!$A$3:$A$13,0)),"(unmapped)")),IFERROR(INDEX(Mapping!$B$17:$B$22,MATCH($F21,Mapping!$A$17:$A$22,0)),$F21)&" "&IF($G21="Banking","Banking",IFERROR(INDEX(Mapping!$E$17:$E$28,MATCH($J21,Mapping!$D$17:$D$28,0)),"(unmapped)"))))) -> AR IB
A22: ES1101 | B22: 101417 | C22: FRANCISCO JOSE MANZANILLA MULLOR | D22: AP09 | E22: 2026 | F22: R2R | G22: Banking | H22: DSS | I22: 1 | J22: Iberia | K22: =IF($D22="","",IFERROR(INDEX(Mapping!$H$3:$H$32,MATCH($B22,Mapping!$G$3:$G$32,0)),IF(LEFT($F22,3)="P2P",IFERROR(INDEX(Mapping!$E$3:$E$6,MATCH($G22,Mapping!$D$3:$D$6,0)),IFERROR(INDEX(Mapping!$B$3:$B$13,MATCH($J22,Mapping!$A$3:$A$13,0)),"(unmapped)")),IFERROR(INDEX(Mapping!$B$17:$B$22,MATCH($F22,Mapping!$A$17:$A$22,0)),$F22)&" "&IF($G22="Banking","Banking",IFERROR(INDEX(Mapping!$E$17:$E$28,MATCH($J22,Mapping!$D$17:$D$28,0)),"(unmapped)"))))) -> R2R Banking
A23: ES1101 | B23: 101425 | C23: MARÍA DEL CARMEN CONDE SAN JOSÉ | D23: AP09 | E23: 2026 | F23: Q2C | H23: DSS | I23: 1 | J23: Iberia | K23: =IF($D23="","",IFERROR(INDEX(Mapping!$H$3:$H$32,MATCH($B23,Mapping!$G$3:$G$32,0)),IF(LEFT($F23,3)="P2P",IFERROR(INDEX(Mapping!$E$3:$E$6,MATCH($G23,Mapping!$D$3:$D$6,0)),IFERROR(INDEX(Mapping!$B$3:$B$13,MATCH($J23,Mapping!$A$3:$A$13,0)),"(unmapped)")),IFERROR(INDEX(Mapping!$B$17:$B$22,MATCH($F23,Mapping!$A$17:$A$22,0)),$F23)&" "&IF($G23="Banking","Banking",IFERROR(INDEX(Mapping!$E$17:$E$28,MATCH($J23,Mapping!$D$17:$D$28,0)),"(unmapped)"))))) -> AR IB
A24: ES1101 | B24: 101426 | C24: RAÚL VIÑAS ZAMORA | D24: AP09 | E24: 2026 | F24: P2P | H24: DSS | I24: 1 | J24: Iberia | K24: =IF($D24="","",IFERROR(INDEX(Mapping!$H$3:$H$32,MATCH($B24,Mapping!$G$3:$G$32,0)),IF(LEFT($F24,3)="P2P",IFERROR(INDEX(Mapping!$E$3:$E$6,MATCH($G24,Mapping!$D$3:$D$6,0)),IFERROR(INDEX(Mapping!$B$3:$B$13,MATCH($J24,Mapping!$A$3:$A$13,0)),"(unmapped)")),IFERROR(INDEX(Mapping!$B$17:$B$22,MATCH($F24,Mapping!$A$17:$A$22,0)),$F24)&" "&IF($G24="Banking","Banking",IFERROR(INDEX(Mapping!$E$17:$E$28,MATCH($J24,Mapping!$D$17:$D$28,0)),"(unmapped)"))))) -> AP IB
A25: ES1101 | B25: 101429 | C25: MARIA EVA ALVARO REDONDO | D25: AP09 | E25: 2026 | F25: Q2C | G25: Banking | H25: DSS | I25: 1 | J25: Iberia | K25: =IF($D25="","",IFERROR(INDEX(Mapping!$H$3:$H$32,MATCH($B25,Mapping!$G$3:$G$32,0)),IF(LEFT($F25,3)="P2P",IFERROR(INDEX(Mapping!$E$3:$E$6,MATCH($G25,Mapping!$D$3:$D$6,0)),IFERROR(INDEX(Mapping!$B$3:$B$13,MATCH($J25,Mapping!$A$3:$A$13,0)),"(unmapped)")),IFERROR(INDEX(Mapping!$B$17:$B$22,MATCH($F25,Mapping!$A$17:$A$22,0)),$F25)&" "&IF($G25="Banking","Banking",IFERROR(INDEX(Mapping!$E$17:$E$28,MATCH($J25,Mapping!$D$17:$D$28,0)),"(unmapped)"))))) -> AR Banking
A26: ES1101 | B26: 101430 | C26: ALBA FERNÁNDEZ LÓPEZ | D26: AP09 | E26: 2026 | F26: P2P Vuelta | H26: DSS | I26: 1 | J26: NL | K26: =IF($D26="","",IFERROR(INDEX(Mapping!$H$3:$H$32,MATCH($B26,Mapping!$G$3:$G$32,0)),IF(LEFT($F26,3)="P2P",IFERROR(INDEX(Mapping!$E$3:$E$6,MATCH($G26,Mapping!$D$3:$D$6,0)),IFERROR(INDEX(Mapping!$B$3:$B$13,MATCH($J26,Mapping!$A$3:$A$13,0)),"(unmapped)")),IFERROR(INDEX(Mapping!$B$17:$B$22,MATCH($F26,Mapping!$A$17:$A$22,0)),$F26)&" "&IF($G26="Banking","Banking",IFERROR(INDEX(Mapping!$E$17:$E$28,MATCH($J26,Mapping!$D$17:$D$28,0)),"(unmapped)"))))) -> P2P Vuelta BE
A27: ES1101 | B27: 101434 | C27: ALFONSO BARRIOS RABAZAS | D27: AP09 | E27: 2026 | F27: DM | H27: DSS | I27: 1 | J27: Iberia | K27: =IF($D27="","",IFERROR(INDEX(Mapping!$H$3:$H$32,MATCH($B27,Mapping!$G$3:$G$32,0)),IF(LEFT($F27,3)="P2P",IFERROR(INDEX(Mapping!$E$3:$E$6,MATCH($G27,Mapping!$D$3:$D$6,0)),IFERROR(INDEX(Mapping!$B$3:$B$13,MATCH($J27,Mapping!$A$3:$A$13,0)),"(unmapped)")),IFERROR(INDEX(Mapping!$B$17:$B$22,MATCH($F27,Mapping!$A$17:$A$22,0)),$F27)&" "&IF($G27="Banking","Banking",IFERROR(INDEX(Mapping!$E$17:$E$28,MATCH($J27,Mapping!$D$17:$D$28,0)),"(unmapped)"))))) -> MD IB
A28: ES1101 | B28: 101436 | C28: ISABEL DAMASO | D28: AP09 | E28: 2026 | F28: P2P Vuelta | G28: Helpdesk | H28: DSS | I28: 1 | J28: UK | K28: =IF($D28="","",IFERROR(INDEX(Mapping!$H$3:$H$32,MATCH($B28,Mapping!$G$3:$G$32,0)),IF(LEFT($F28,3)="P2P",IFERROR(INDEX(Mapping!$E$3:$E$6,MATCH($G28,Mapping!$D$3:$D$6,0)),IFERROR(INDEX(Mapping!$B$3:$B$13,MATCH($J28,Mapping!$A$3:$A$13,0)),"(unmapped)")),IFERROR(INDEX(Mapping!$B$17:$B$22,MATCH($F28,Mapping!$A$17:$A$22,0)),$F28)&" "&IF($G28="Banking","Banking",IFERROR(INDEX(Mapping!$E$17:$E$28,MATCH($J28,Mapping!$D$17:$D$28,0)),"(unmapped)"))))) -> P2P Vuelta UK
A29: ES1101 | B29: 101437 | C29: IRIS LÓPEZ ALMARAZ | D29: AP09 | E29: 2026 | F29: P2P Vuelta | H29: DSS | I29: 1 | J29: DE | K29: =IF($D29="","",IFERROR(INDEX(Mapping!$H$3:$H$32,MATCH($B29,Mapping!$G$3:$G$32,0)),IF(LEFT($F29,3)="P2P",IFERROR(INDEX(Mapping!$E$3:$E$6,MATCH($G29,Mapping!$D$3:$D$6,0)),IFERROR(INDEX(Mapping!$B$3:$B$13,MATCH($J29,Mapping!$A$3:$A$13,0)),"(unmapped)")),IFERROR(INDEX(Mapping!$B$17:$B$22,MATCH($F29,Mapping!$A$17:$A$22,0)),$F29)&" "&IF($G29="Banking","Banking",IFERROR(INDEX(Mapping!$E$17:$E$28,MATCH($J29,Mapping!$D$17:$D$28,0)),"(unmapped)"))))) -> P2P Vuelta DE
A30: ES1101 | B30: 101438 | C30: ANA MARÍA NUÑEZ MAGRO | D30: AP09 | E30: 2026 | F30: R2R | H30: DSS | I30: 1 | J30: Iberia | K30: =IF($D30="","",IFERROR(INDEX(Mapping!$H$3:$H$32,MATCH($B30,Mapping!$G$3:$G$32,0)),IF(LEFT($F30,3)="P2P",IFERROR(INDEX(Mapping!$E$3:$E$6,MATCH($G30,Mapping!$D$3:$D$6,0)),IFERROR(INDEX(Mapping!$B$3:$B$13,MATCH($J30,Mapping!$A$3:$A$13,0)),"(unmapped)")),IFERROR(INDEX(Mapping!$B$17:$B$22,MATCH($F30,Mapping!$A$17:$A$22,0)),$F30)&" "&IF($G30="Banking","Banking",IFERROR(INDEX(Mapping!$E$17:$E$28,MATCH($J30,Mapping!$D$17:$D$28,0)),"(unmapped)"))))) -> R2R IB
A31: ES1101 | B31: 101442 | C31: PABLO LUIS MARTIN ARRIBAS | D31: AP09 | E31: 2026 | F31: R2R | H31: IP | I31: 1 | J31: Iberia | K31: =IF($D31="","",IFERROR(INDEX(Mapping!$H$3:$H$32,MATCH($B31,Mapping!$G$3:$G$32,0)),IF(LEFT($F31,3)="P2P",IFERROR(INDEX(Mapping!$E$3:$E$6,MATCH($G31,Mapping!$D$3:$D$6,0)),IFERROR(INDEX(Mapping!$B$3:$B$13,MATCH($J31,Mapping!$A$3:$A$13,0)),"(unmapped)")),IFERROR(INDEX(Mapping!$B$17:$B$22,MATCH($F31,Mapping!$A$17:$A$22,0)),$F31)&" "&IF($G31="Banking","Banking",IFERROR(INDEX(Mapping!$E$17:$E$28,MATCH($J31,Mapping!$D$17:$D$28,0)),"(unmapped)"))))) -> R2R IB
A32: ES1101 | B32: 101443 | C32: DANIEL MENDEZ SILVA | D32: AP09 | E32: 2026 | F32: R2R | G32: Banking | H32: DSS | I32: 1 | J32: Iberia | K32: =IF($D32="","",IFERROR(INDEX(Mapping!$H$3:$H$32,MATCH($B32,Mapping!$G$3:$G$32,0)),IF(LEFT($F32,3)="P2P",IFERROR(INDEX(Mapping!$E$3:$E$6,MATCH($G32,Mapping!$D$3:$D$6,0)),IFERROR(INDEX(Mapping!$B$3:$B$13,MATCH($J32,Mapping!$A$3:$A$13,0)),"(unmapped)")),IFERROR(INDEX(Mapping!$B$17:$B$22,MATCH($F32,Mapping!$A$17:$A$22,0)),$F32)&" "&IF($G32="Banking","Banking",IFERROR(INDEX(Mapping!$E$17:$E$28,MATCH($J32,Mapping!$D$17:$D$28,0)),"(unmapped)"))))) -> R2R Banking
A33: ES1101 | B33: 101448 | C33: MARCIA PRADO ARGIBAY | D33: AP09 | E33: 2026 | F33: Q2C | H33: DSS | I33: 1 | J33: Iberia | K33: =IF($D33="","",IFERROR(INDEX(Mapping!$H$3:$H$32,MATCH($B33,Mapping!$G$3:$G$32,0)),IF(LEFT($F33,3)="P2P",IFERROR(INDEX(Mapping!$E$3:$E$6,MATCH($G33,Mapping!$D$3:$D$6,0)),IFERROR(INDEX(Mapping!$B$3:$B$13,MATCH($J33,Mapping!$A$3:$A$13,0)),"(unmapped)")),IFERROR(INDEX(Mapping!$B$17:$B$22,MATCH($F33,Mapping!$A$17:$A$22,0)),$F33)&" "&IF($G33="Banking","Banking",IFERROR(INDEX(Mapping!$E$17:$E$28,MATCH($J33,Mapping!$D$17:$D$28,0)),"(unmapped)"))))) -> AR IB
A34: ES1101 | B34: 101451 | C34: RUT ALVAREZ DOMINGUEZ | D34: AP09 | E34: 2026 | F34: R2R | H34: DSS | I34: 1 | J34: Iberia | K34: =IF($D34="","",IFERROR(INDEX(Mapping!$H$3:$H$32,MATCH($B34,Mapping!$G$3:$G$32,0)),IF(LEFT($F34,3)="P2P",IFERROR(INDEX(Mapping!$E$3:$E$6,MATCH($G34,Mapping!$D$3:$D$6,0)),IFERROR(INDEX(Mapping!$B$3:$B$13,MATCH($J34,Mapping!$A$3:$A$13,0)),"(unmapped)")),IFERROR(INDEX(Mapping!$B$17:$B$22,MATCH($F34,Mapping!$A$17:$A$22,0)),$F34)&" "&IF($G34="Banking","Banking",IFERROR(INDEX(Mapping!$E$17:$E$28,MATCH($J34,Mapping!$D$17:$D$28,0)),"(unmapped)"))))) -> R2R IB
A35: ES1101 | B35: 101458 | C35: JENNIFER CAROLINA JUANEDA PALACIOS | D35: AP09 | E35: 2026 | F35: P2P Vuelta | H35: DSS | I35: 1 | J35: UK | K35: =IF($D35="","",IFERROR(INDEX(Mapping!$H$3:$H$32,MATCH($B35,Mapping!$G$3:$G$32,0)),IF(LEFT($F35,3)="P2P",IFERROR(INDEX(Mapping!$E$3:$E$6,MATCH($G35,Mapping!$D$3:$D$6,0)),IFERROR(INDEX(Mapping!$B$3:$B$13,MATCH($J35,Mapping!$A$3:$A$13,0)),"(unmapped)")),IFERROR(INDEX(Mapping!$B$17:$B$22,MATCH($F35,Mapping!$A$17:$A$22,0)),$F35)&" "&IF($G35="Banking","Banking",IFERROR(INDEX(Mapping!$E$17:$E$28,MATCH($J35,Mapping!$D$17:$D$28,0)),"(unmapped)"))))) -> P2P Vuelta UK
A36: ES1101 | B36: 101460 | C36: NESTOR NIETO RAPOSO | D36: AP09 | E36: 2026 | F36: R2R | H36: DSS | I36: 0.875 | J36: Iberia | K36: =IF($D36="","",IFERROR(INDEX(Mapping!$H$3:$H$32,MATCH($B36,Mapping!$G$3:$G$32,0)),IF(LEFT($F36,3)="P2P",IFERROR(INDEX(Mapping!$E$3:$E$6,MATCH($G36,Mapping!$D$3:$D$6,0)),IFERROR(INDEX(Mapping!$B$3:$B$13,MATCH($J36,Mapping!$A$3:$A$13,0)),"(unmapped)")),IFERROR(INDEX(Mapping!$B$17:$B$22,MATCH($F36,Mapping!$A$17:$A$22,0)),$F36)&" "&IF($G36="Banking","Banking",IFERROR(INDEX(Mapping!$E$17:$E$28,MATCH($J36,Mapping!$D$17:$D$28,0)),"(unmapped)"))))) -> R2R IB
A37: ES1101 | B37: 102348 | C37: HECTOR CRESPO SOUSA | D37: AP09 | E37: 2026 | F37: P2P Vuelta | G37: Banking | H37: DSS | I37: 1 | J37: DE | K37: =IF($D37="","",IFERROR(INDEX(Mapping!$H$3:$H$32,MATCH($B37,Mapping!$G$3:$G$32,0)),IF(LEFT($F37,3)="P2P",IFERROR(INDEX(Mapping!$E$3:$E$6,MATCH($G37,Mapping!$D$3:$D$6,0)),IFERROR(INDEX(Mapping!$B$3:$B$13,MATCH($J37,Mapping!$A$3:$A$13,0)),"(unmapped)")),IFERROR(INDEX(Mapping!$B$17:$B$22,MATCH($F37,Mapping!$A$17:$A$22,0)),$F37)&" "&IF($G37="Banking","Banking",IFERROR(INDEX(Mapping!$E$17:$E$28,MATCH($J37,Mapping!$D$17:$D$28,0)),"(unmapped)"))))) -> P2P Vuelta Banking
A38: ES1101 | B38: 102349 | C38: ELENA CARRASCAL CANO | D38: AP09 | E38: 2026 | F38: P2P Vuelta | H38: DSS | I38: 1 | J38: Benelux | K38: =IF($D38="","",IFERROR(INDEX(Mapping!$H$3:$H$32,MATCH($B38,Mapping!$G$3:$G$32,0)),IF(LEFT($F38,3)="P2P",IFERROR(INDEX(Mapping!$E$3:$E$6,MATCH($G38,Mapping!$D$3:$D$6,0)),IFERROR(INDEX(Mapping!$B$3:$B$13,MATCH($J38,Mapping!$A$3:$A$13,0)),"(unmapped)")),IFERROR(INDEX(Mapping!$B$17:$B$22,MATCH($F38,Mapping!$A$17:$A$22,0)),$F38)&" "&IF($G38="Banking","Banking",IFERROR(INDEX(Mapping!$E$17:$E$28,MATCH($J38,Mapping!$D$17:$D$28,0)),"(unmapped)"))))) -> P2P Vuelta BE
A39: ES1101 | B39: 102394 | C39: RUTH TEREFE GEBREYES | D39: AP09 | E39: 2026 | F39: P2P Vuelta | G39: Helpdesk | H39: DSS | I39: 1 | J39: NL | K39: =IF($D39="","",IFERROR(INDEX(Mapping!$H$3:$H$32,MATCH($B39,Mapping!$G$3:$G$32,0)),IF(LEFT($F39,3)="P2P",IFERROR(INDEX(Mapping!$E$3:$E$6,MATCH($G39,Mapping!$D$3:$D$6,0)),IFERROR(INDEX(Mapping!$B$3:$B$13,MATCH($J39,Mapping!$A$3:$A$13,0)),"(unmapped)")),IFERROR(INDEX(Mapping!$B$17:$B$22,MATCH($F39,Mapping!$A$17:$A$22,0)),$F39)&" "&IF($G39="Banking","Banking",IFERROR(INDEX(Mapping!$E$17:$E$28,MATCH($J39,Mapping!$D$17:$D$28,0)),"(unmapped)"))))) -> P2P Vuelta BE
A40: ES1101 | B40: 102397 | C40: MARIA MARTINEZ SIMÓN | D40: AP09 | E40: 2026 | F40: R2R | H40: DSS | I40: 1 | J40: Iberia | K40: =IF($D40="","",IFERROR(INDEX(Mapping!$H$3:$H$32,MATCH($B40,Mapping!$G$3:$G$32,0)),IF(LEFT($F40,3)="P2P",IFERROR(INDEX(Mapping!$E$3:$E$6,MATCH($G40,Mapping!$D$3:$D$6,0)),IFERROR(INDEX(Mapping!$B$3:$B$13,MATCH($J40,Mapping!$A$3:$A$13,0)),"(unmapped)")),IFERROR(INDEX(Mapping!$B$17:$B$22,MATCH($F40,Mapping!$A$17:$A$22,0)),$F40)&" "&IF($G40="Banking","Banking",IFERROR(INDEX(Mapping!$E$17:$E$28,MATCH($J40,Mapping!$D$17:$D$28,0)),"(unmapped)"))))) -> R2R IB
...

Sheet DIV table
A1: Label | B1: Div | C1: Subdivisión | E1: This table is the one that organises the divisions
A2: DE_Pack | B2: DE | C2: DE
A3: FR_Qualiac | B3: FR | C3: FR
A4: FR_Navision | B4: FR | C4: FR
A5: IT_Paper | B5: IT | C5: IT
A6: BE_Pack | B6: BE | C6: BE
A7: NL_Pack | B7: BE | C7: BE
A8: NL_PMS | B8: PMS | C8: PMS
A9: UK_TMS | B9: TMS | C9: TMS
A10: NL_Paper | B10: PS | C10: PS
A11: UK_Pack | B11: UK | C11: UK
A12: UK_Paper | B12: UK | C12: UK
A13: UK_PLC | B13: UK | C13: UK
... A23: Paper FR | B23: - | C23: FR

Sheet Mapping
A1: P2P only: Team → AP category | D1: P2P only: Sub-process → AP category | G1: EXCEPTIONS by employee (highest priority)
A2: Team | B2: Category | D2: Sub-process | E2: Category | G2: Employee no. | H2: Category | I2: Name (auto)
A3: DE | B3: AP DE | D3: Banking | E3: Banking | I3: =IF($G3="","",IFERROR(INDEX(Payroll!$C:$C,MATCH($G3,Payroll!$B:$B,0)),"(not found)"))
A4: FR | B4: AP FR | D4: Helpdesk | E4: AP Help Desk | I4: =IF($G4="","",IFERROR(INDEX(Payroll!$C:$C,MATCH($G4,Payroll!$B:$B,0)),"(not found)"))
A5: Iberia | B5: AP IB | D5: Manager | E5: AP Manager | I5: =IF($G5="","",IFERROR(INDEX(Payroll!$C:$C,MATCH($G5,Payroll!$B:$B,0)),"(not found)"))
A6: UK | B6: AP UK | D6: General | E6: AP General | I6: =IF($G6="","",IFERROR(INDEX(Payroll!$C:$C,MATCH($G6,Payroll!$B:$B,0)),"(not found)"))
A7: Benelux | B7: AP BE | I7: =IF($G7="","",IFERROR(INDEX(Payroll!$C:$C,MATCH($G7,Payroll!$B:$B,0)),"(not found)"))
A8: IT | B8: AP IT | I8: =IF($G8="","",IFERROR(INDEX(Payroll!$C:$C,MATCH($G8,Payroll!$B:$B,0)),"(not found)"))
A9: PS | B9: AP PS | I9: =IF($G9="","",IFERROR(INDEX(Payroll!$C:$C,MATCH($G9,Payroll!$B:$B,0)),"(not found)"))
A10: General | B10: AP General | I10: =IF($G10="","",IFERROR(INDEX(Payroll!$C:$C,MATCH($G10,Payroll!$B:$B,0)),"(not found)"))
A11: Mejora | B11: AP Continuos improvement | I11: =IF($G11="","",IFERROR(INDEX(Payroll!$C:$C,MATCH($G11,Payroll!$B:$B,0)),"(not found)"))
A12: MA | B12: AP MA | I12: =IF($G12="","",IFERROR(INDEX(Payroll!$C:$C,MATCH($G12,Payroll!$B:$B,0)),"(not found)"))
A13: NL | B13: AP BE | I13: =IF($G13="","",IFERROR(INDEX(Payroll!$C:$C,MATCH($G13,Payroll!$B:$B,0)),"(not found)"))
I14: =IF($G14="","",IFERROR(INDEX(Payroll!$C:$C,MATCH($G14,Payroll!$B:$B,0)),"(not found)"))
A15: Other processes: Process → label | D15: Other processes: Team → country code | I15: =IF($G15="","",IFERROR(INDEX(Payroll!$C:$C,MATCH($G15,Payroll!$B:$B,0)),"(not found)"))
A16: Process | B16: Label | D16: Team | E16: Country | I16: =IF($G16="","",IFERROR(INDEX(Payroll!$C:$C,MATCH($G16,Payroll!$B:$B,0)),"(not found)"))
A17: Q2C | B17: AR | D17: Iberia | E17: IB | I17: =IF($G17="","",IFERROR(INDEX(Payroll!$C:$C,MATCH($G17,Payroll!$B:$B,0)),"(not found)"))
A18: O2C | B18: AR | D18: FR | E18: FR | I18: =IF($G18="","",IFERROR(INDEX(Payroll!$C:$C,MATCH($G18,Payroll!$B:$B,0)),"(not found)"))
A19: R2R | B19: R2R | D19: IT | E19: IT | I19: =IF($G19="","",IFERROR(INDEX(Payroll!$C:$C,MATCH($G19,Payroll!$B:$B,0)),"(not found)"))
A20: HR | B20: HR | D20: MA | E20: MA | I20: =IF($G20="","",IFERROR(INDEX(Payroll!$C:$C,MATCH($G20,Payroll!$B:$B,0)),"(not found)"))
A21: DM | B21: MD | D21: DE | E21: DE | I21: =IF($G21="","",IFERROR(INDEX(Payroll!$C:$C,MATCH($G21,Payroll!$B:$B,0)),"(not found)"))
A22: OoS | B22: OoS | D22: UK | E22: UK | I22: =IF($G22="","",IFERROR(INDEX(Payroll!$C:$C,MATCH($G22,Payroll!$B:$B,0)),"(not found)"))
D23: Benelux | E23: BE | I23: =IF($G23="","",IFERROR(INDEX(Payroll!$C:$C,MATCH($G23,Payroll!$B:$B,0)),"(not found)"))
D24: NL | E24: BE | I24: =IF($G24="","",IFERROR(INDEX(Payroll!$C:$C,MATCH($G24,Payroll!$B:$B,0)),"(not found)"))
D25: PS | E25: PS | I25: =IF($G25="","",IFERROR(INDEX(Payroll!$C:$C,MATCH($G25,Payroll!$B:$B,0)),"(not found)"))
D26: Kunheim | E26: Kunheim | I26: =IF($G26="","",IFERROR(INDEX(Payroll!$C:$C,MATCH($G26,Payroll!$B:$B,0)),"(not found)"))
D27: Mejora | E27: Improvement | I27: =IF($G27="","",IFERROR(INDEX(Payroll!$C:$C,MATCH($G27,Payroll!$B:$B,0)),"(not found)"))
D28: General | E28: General | I28: =IF($G28="","",IFERROR(INDEX(Payroll!$C:$C,MATCH($G28,Payroll!$B:$B,0)),"(not found)"))
I29: =IF($G29="","",IFERROR(INDEX(Payroll!$C:$C,MATCH($G29,Payroll!$B:$B,0)),"(not found)"))
I30: =IF($G30="","",IFERROR(INDEX(Payroll!$C:$C,MATCH($G30,Payroll!$B:$B,0)),"(not found)"))
I31: =IF($G31="","",IFERROR(INDEX(Payroll!$C:$C,MATCH($G31,Payroll!$B:$B,0)),"(not found)"))
I32: =IF($G32="","",IFERROR(INDEX(Payroll!$C:$C,MATCH($G32,Payroll!$B:$B,0)),"(not found)"))

Sheet Instrucciones
A1: INSTRUCCIONES · Control mensual de FTE (el libro está en inglés)
A3: Qué hace este fichero
A4: Compara, para el periodo elegido, los FTE que constan en la NÓMINA ('Payroll') con los FTE reportados en el SCORECARD, por proceso (P2P/AP, AR, R2R) y por país. La diferencia se calcula sola y se marca con un semáforo.
A6: Uso mensual (2 pasos)
A7: 1. Actualiza los datos: pega la nómina del mes en la hoja 'Payroll' y actualiza la hoja 'FTE Scorecard', cambiar el filtro por el mes actual en la consulta combinar 2
A8: 2. En 'FTE Reconciliation' escribe el periodo en la celda I1 (p. ej. AP07) y el año en K1. Todo se recalcula solo.
A10: Hojas del libro
A11: Hoja | B11: Para qué sirve | C11: ¿La tocas?
A12: FTE Reconciliation | B12: Cuadre del negocio DSS (BAU). Hoja de presentación. | C12: Solo I1 (periodo) y K1 (año), más las columnas amarillas C, D y E.
A13: IP Reconciliation | B13: Mismo cuadre para el negocio IP. Aún no hay Scorecard de IP: la columna F (FTE Scorecard) es entrada manual hasta que llegue. | C13: I1, K1 y las columnas amarillas C, D, E y F.
A14: Payroll | B14: Detalle por persona. La columna K clasifica sola cada persona. | C14: Pegar los datos del mes (columnas A a J).
A15: FTE Scorecard | B15: FTE reportados por país, mes y definición. | C15: Pegar / actualizar.
A16: Mapping | B16: Reglas que traducen cada persona a su fila de la hoja de cuadre. | C16: Solo al cambiar equipos o funciones.
A17: Summary | B17: Análisis previo, se conserva como referencia. | C17: No.
A18: DIV table | B18: Tabla auxiliar de divisiones. | C18: No.
A20: Cómo se leen las columnas de la hoja de cuadre
A21: Columna | B21: Significado
A22: B · Payroll FTE | B22: Personas en nómina del periodo (se extrae de la hoja 'Payroll'). Fórmula: no tocar.
A23: C · Vacancy | B23: Vacantes. Entrada manual.
A24: D · Sick leave | B24: Bajas. Entrada manual.
A25: E · Adjustment | B25: Ajustes. Entrada manual.
A26: F · FTE Scorecard | B26: FTE reportados en el Scorecard. Fórmula: no tocar.
A27: H a L · Breakdown | B27: Reparto del FTE del Scorecard por rol. Entrada manual.
A28: M · Difference | B28: Descuadre: C + D + E + F − B.
A29: N · Status | B29: Semáforo automático: OK si la diferencia está dentro de ±0,02; Review en el resto de casos.
A30: O · Comments | B30: Justificación de la diferencia. Entrada manual.
A31: Color de M | B31: Verde: la diferencia está dentro de ±0,02 (cuadra). Rojo: fuera de ese margen.
A33: Control: que no se escape nadie
A34: Al pie de cada cuadre hay cuatro filas encadenadas: B27 Subtotal (suma de los procesos de arriba) + B28 Out of scope (OoS) frente a B29 TOTAL PAYROLL, que suma toda la nómina del negocio y del periodo directamente de la hoja 'Payroll'. B30 es la diferencia sin explicar y debe ser 0.
A35: Si B30 no es 0, hay líneas de nómina que no está recogiendo ninguna fila: normalmente un proceso nuevo que no tiene fila propia, o una persona cuya categoría queda como (unmapped) por un Team o Subproceso que falta en 'Mapping'. La nota del pie indica cuántas filas están sin mapear.
A37: Comentarios y categorías
A38: Comentarios: escribe directamente en la columna O (Comments) de cada hoja de cuadre la justificación de la diferencia. El fichero es de un solo periodo, así que no se guarda histórico: cada mes se parte de un fichero nuevo.
A39: Categorías: AP solo existe dentro del proceso P2P, así que las filas AP se alimentan del mapeo Team → categoría AP y del mapeo Subproceso → categoría AP (tablas de la izquierda de 'Mapping'). En el resto de procesos la categoría es Proceso + Team (por ejemplo Q2C Iberia, R2R Iberia, HR Iberia), usando la tabla Team → etiqueta. Si una persona debe ir en otra categoría, añádela en EXCEPCIONES (columnas G y H de 'Mapping'): manda sobre todo lo demás. El proceso puede venir como 'P2P' o como 'P2P Vuelta': las formulas tratan las dos variantes como P2P (cualquier proceso que empiece por P2P), de modo que esas personas caen en las filas AP igual que el resto.
A41: Notas técnicas
A42: · Las fórmulas usan referencias de columna completa: admiten cualquier número de filas, aumenten o disminuyan.
A43: · La columna K de 'Payroll' está preparada hasta la fila 5000 (unos 30 meses). La nota del pie (A32) avisa si se supera.
A44: · El libro no contiene macros.
